<?xml version="1.0" encoding="utf-8"?>
<!-- =================================================================================== -->
<!-- |    This document was autogenerated by xacro from /home/andi/catkin_redevel_ws/src/hada_explorer_bot/hada_explorer_description/urdf/h500.urdf.xacro | -->
<!-- |    EDITING THIS FILE BY HAND IS NOT RECOMMENDED                                 | -->
<!-- =================================================================================== -->
<robot name="h500_sprayer" xmlns:xacro="http://wiki.ros.org/xacro">
  <xacro:property name="robot_namespace" value="/hada_bot"/>  
  <!-- =============== Link & Joint =============== -->
  <!-- realsense camera -->
  <material name="aluminum">
    <color rgba="0.5 0.5 0.5 1"/>
  </material>
  <material name="plastic">
    <color rgba="0.1 0.1 0.1 1"/>
  </material>
  <material name="invisible">
    <color rgba="0 0 0 0"/>
  </material>
  <material name="green">
    <color rgba="0 1 0 1"/>
  </material>
  <material name="grey">
    <color rgba="0.9 0.9 0.9 1"/>
  </material>

  <link name="base_link"/>
  <!-- camera body, with origin at bottom screw mount -->
  <joint name="camera_joint" type="fixed">
    <origin rpy="0 0 0" xyz="0 0 0"/>
    <parent link="base_link"/>
    <child link="camera_bottom_screw_frame"/>
  </joint>
  <link name="camera_bottom_screw_frame"/>
  <joint name="camera_link_joint" type="fixed">
    <origin rpy="0 0 0" xyz="0.0106 0.0175 0.0125"/>
    <parent link="camera_bottom_screw_frame"/>
    <child link="camera_link"/>
  </joint>
  <link name="camera_link">
    <visual>
      <!-- the mesh origin is at front plate in between the two infrared camera axes -->
      <origin rpy="1.57079632679 0 1.57079632679" xyz="0.0043 -0.0175 0"/>
      <geometry>
        <mesh filename="package://realsense2_description/meshes/d435.stl"/>
      </geometry>
    </visual>
    <collision>
      <origin rpy="0 0 0" xyz="0 -0.0175 0"/>
      <geometry>
        <box size="0.02505 0.09 0.025"/>
      </geometry>
    </collision>
    <inertial>
      <!-- The following are not reliable values, and should not be used for modeling -->
      <mass value="0.072"/>
      <origin xyz="0 0 0"/>
      <inertia ixx="0.003881243" ixy="0.0" ixz="0.0" iyy="0.000498940" iyz="0.0" izz="0.003879257"/>
    </inertial>
  </link>
  <!-- camera depth joints and links -->
  <joint name="camera_depth_joint" type="fixed">
    <origin rpy="0 0 0" xyz="0 0 0"/>
    <parent link="camera_link"/>
    <child link="camera_depth_frame"/>
  </joint>
  <link name="camera_depth_frame"/>
  <joint name="camera_depth_optical_joint" type="fixed">
    <origin rpy="-1.57079632679 0 -1.57079632679" xyz="0 0 0"/>
    <parent link="camera_depth_frame"/>
    <child link="camera_depth_optical_frame"/>
  </joint>
  <link name="camera_depth_optical_frame"/>
  <!-- camera left IR joints and links -->
  <joint name="camera_infra1_joint" type="fixed">
    <origin rpy="0 0 0" xyz="0 0.0 0"/>
    <parent link="camera_link"/>
    <child link="camera_infra1_frame"/>
  </joint>
  <link name="camera_infra1_frame"/>
  <joint name="camera_infra1_optical_joint" type="fixed">
    <origin rpy="-1.57079632679 0 -1.57079632679" xyz="0 0 0"/>
    <parent link="camera_infra1_frame"/>
    <child link="camera_infra1_optical_frame"/>
  </joint>
  <link name="camera_infra1_optical_frame"/>
  <!-- camera right IR joints and links -->
  <joint name="camera_infra2_joint" type="fixed">
    <origin rpy="0 0 0" xyz="0 -0.05 0"/>
    <parent link="camera_link"/>
    <child link="camera_infra2_frame"/>
  </joint>
  <link name="camera_infra2_frame"/>
  <joint name="camera_infra2_optical_joint" type="fixed">
    <origin rpy="-1.57079632679 0 -1.57079632679" xyz="0 0 0"/>
    <parent link="camera_infra2_frame"/>
    <child link="camera_infra2_optical_frame"/>
  </joint>
  <link name="camera_infra2_optical_frame"/>
  <!-- camera color joints and links -->
  <joint name="camera_color_joint" type="fixed">
    <origin rpy="0 0 0" xyz="0 0.015 0"/>
    <parent link="camera_link"/>
    <child link="camera_color_frame"/>
  </joint>
  <link name="camera_color_frame"/>
  <joint name="camera_color_optical_joint" type="fixed">
    <origin rpy="-1.57079632679 0 -1.57079632679" xyz="0 0 0"/>
    <parent link="camera_color_frame"/>
    <child link="camera_color_optical_frame"/>
  </joint>
  <link name="camera_color_optical_frame"/>
  <material name="blue">
    <color rgba="0 0 0.8 1"/>
  </material>
  <material name="red">
    <color rgba="1 0 0 1"/>
  </material>
  <material name="white">
    <color rgba="1 1 1 1"/>
  </material>

  <!-- camera and frame joint -->  
  <link name="rbot_base2">
    <visual>
      <geometry>
        <box size="0.045 0.09 0.03"/>
      </geometry>
      <origin rpy="0 0 0" xyz="0 0 0"/>
      <material name="red"/>
    </visual>
  </link>
  <link name="servo_bottom2">
    <visual>
      <geometry>
        <cylinder length="0.25" radius="0.015"/>
      </geometry>
      <origin rpy="0 0 0" xyz="0 0 0"/>
      <material name="green"/>
    </visual>
  </link> 

  <link name="up_mount2">
    <visual>
      <geometry>
        <box size="0.05 0.148 0.05"/>
      </geometry>
      <origin rpy="0 0. 0" xyz="0 0 0"/>
      <material name="blue"/>
    </visual>
  </link>

 <joint name="base_to_Servo_B2" type="fixed">
    <parent link="rbot_base2"/>
    <child link="servo_bottom2"/>
    <origin xyz="0 0 0.14"/>
  </joint>
 <joint name="servo_bottom_to_up_mount2" type="fixed">
    <parent link="servo_bottom2"/>
    <child link="up_mount2"/>
    <origin xyz="0 0 0.15"/>
  </joint>
  <joint name="mount_to_camera2" type="fixed">
    <parent link="up_mount2"/>
    <child link="base_link"/>
    <origin rpy="0 0 0" xyz="0.03 0 0.001"/>
  </joint>

  <!-- imu on camera -->
  <link name="imu_link">
    <visual>
      <geometry>
        <box size="0.05 0.026 0.05"/>
      </geometry>
      <material name="green"/>
    </visual>
  </link>
    
  <joint name="imu_joint" type="fixed">
    <origin rpy="0 0 0" xyz="0.0 0.0 0.28"/>
    <parent link="rbot_base2"/>
    <child link="imu_link"/>
  </joint>    

  <!-- robot_base to frame stand camera base -->
  <joint name="baseto_framestand" type="fixed">
    <origin rpy="0 0 0" xyz="0.85 0 1.00"/>
    <parent link="robot_base"/>
    <child link="rbot_base2"/>
  </joint>

  <!-- Base -->
  <link name="base_footprint"/>
  <joint name="robot_base_joint" type="fixed">
    <origin rpy="0 0 0" xyz="0 0 0.15"/> <!-- 0 0 0.05 -->
    <parent link="base_footprint"/>
    <child link="robot_base"/>
  </joint>
  <link name="robot_base">
    <visual>
      <geometry>
        <mesh filename="package://h500_description/meshes/STL/base/h500_body.stl"/>
      </geometry>
    </visual>
    <collision>
      <geometry>
        <mesh filename="package://h500_description/meshes/STL/base/h500_body.stl"/>
      </geometry>
    </collision>
    <inertial>
      <origin xyz="0 0 0.017"/>
      <mass value="1.2"/>
      <inertia ixx="0.0001873" ixy="0" ixz="0" iyy="0.000055" iyz="0" izz="0.0002283"/>
    </inertial>
  </link>
  <joint name="front_right_steering_joint" type="revolute">
    <origin xyz="-0.442 0.361 0.0135"/>
    <parent link="robot_base"/>
    <child link="front_right_steering_link"/>
    <limit effort="5" lower="-2.1" upper="2.1" velocity="6.28"/>
    <axis xyz="0 0 2."/>
  </joint>
  <link name="front_right_steering_link">
    <visual>
      <geometry>
        <mesh filename="package://h500_description/meshes/STL/suspension/front_right_link.stl"/>
      </geometry>
    </visual>
    <collision>
      <geometry>
        <mesh filename="package://h500_description/meshes/STL/suspension/front_right_link.stl"/>
      </geometry>
    </collision>
    <inertial>
      <origin xyz="0 0 -0.02"/>
      <mass value="0.15"/>
      <inertia ixx="0.00001" ixy="0" ixz="0" iyy="0.00001" iyz="0" izz="0.000004"/>
    </inertial>
  </link>
  <joint name="front_left_steering_joint" type="revolute">
    <origin xyz="-0.442 -0.3495 0.0135"/>
    <parent link="robot_base"/>
    <child link="front_left_steering_link"/>
    <limit effort="5" lower="-2.1" upper="2.1" velocity="6.28"/>
    <axis xyz="0 0 1"/>
  </joint>
  <link name="front_left_steering_link">
    <visual>
      <geometry>
        <mesh filename="package://h500_description/meshes/STL/suspension/front_left_link.stl"/>
      </geometry>
    </visual>
    <collision>
      <geometry>
        <mesh filename="package://h500_description/meshes/STL/suspension/front_left_link.stl"/>
      </geometry>
    </collision>
    <inertial>
      <origin xyz="0 0 -0.02"/>
      <mass value="0.15"/>
      <inertia ixx="0.00001" ixy="0" ixz="0" iyy="0.00001" iyz="0" izz="0.000004"/>
    </inertial>
  </link>
  <joint name="rear_right_steering_joint" type="revolute">
    <origin xyz="0.676 0.361 0.0135"/>
    <parent link="robot_base"/>
    <child link="rear_right_steering_link"/>
    <limit effort="5" lower="-2.1" upper="2.1" velocity="6.28"/>
    <axis xyz="0 0 1"/>
  </joint>
  <link name="rear_right_steering_link">
    <visual>
      <geometry>
        <mesh filename="package://h500_description/meshes/STL/suspension/rear_right_link.stl"/>
      </geometry>
    </visual>
    <collision>
      <geometry>
        <mesh filename="package://h500_description/meshes/STL/suspension/rear_right_link.stl"/>
      </geometry>
    </collision>
    <inertial>
      <origin xyz="0 0 -0.02"/>
      <mass value="0.15"/>
      <inertia ixx="0.00001" ixy="0" ixz="0" iyy="0.00001" iyz="0" izz="0.000004"/>
    </inertial>
  </link>
  <joint name="rear_left_steering_joint" type="revolute">
    <origin xyz="0.676 -0.3495 0.0135"/>
    <parent link="robot_base"/>
    <child link="rear_left_steering_link"/>
    <limit effort="5" lower="-2.1" upper="2.1" velocity="6.28"/>
    <axis xyz="0 0 1"/>
  </joint>
  <link name="rear_left_steering_link">
    <visual>
      <geometry>
        <mesh filename="package://h500_description/meshes/STL/suspension/rear_left_link.stl"/>
      </geometry>
    </visual>
    <collision>
      <geometry>
        <mesh filename="package://h500_description/meshes/STL/suspension/rear_left_link.stl"/>
      </geometry>
    </collision>
    <inertial>
      <origin xyz="0 0 -0.02"/>
      <mass value="0.15"/>
      <inertia ixx="0.00001" ixy="0" ixz="0" iyy="0.00001" iyz="0" izz="0.000004"/>
    </inertial>
  </link>
  <joint name="ffr_wheel_joint" type="continuous">
    <origin rpy="0 0 3.14159274" xyz="-0.0004 0.07 0.118"/>
    <parent link="front_right_steering_link"/>
    <child link="ffr_wheel_link"/>
    <limit effort="1.5" velocity="20"/>
    <axis xyz="0 1 0"/>
  </joint>
  <link name="ffr_wheel_link">
    <visual>
      <geometry>
        <mesh filename="package://h500_description/meshes/STL/wheel/H500_wheel.stl"/>
      </geometry>
    </visual>
    <collision>
      <geometry>
        <mesh filename="package://h500_description/meshes/STL/wheel/H500_wheel.stl"/>
      </geometry>
    </collision>
    <inertial>
      <origin xyz="0.0 -0.007 -0.0"/>
      <mass value="0.05"/>
      <inertia ixx="0.00001" ixy="0" ixz="0" iyy="0.000018" iyz="0" izz="0.00001"/>
    </inertial>
  </link>
  <joint name="ffl_wheel_joint" type="continuous">
    <origin rpy="0 0 3.14159274" xyz="-0.0004 -0.32 0.118"/>
    <parent link="front_left_steering_link"/>
    <child link="ffl_wheel_link"/>
    <limit effort="1.5" velocity="20"/>
    <axis xyz="0 -1 0"/>
  </joint>
  <link name="ffl_wheel_link">
    <visual>
      <geometry>
        <mesh filename="package://h500_description/meshes/STL/wheel/H500_wheel.stl"/>
      </geometry>
    </visual>
    <collision>
      <geometry>
        <mesh filename="package://h500_description/meshes/STL/wheel/H500_wheel.stl"/>
      </geometry>
    </collision>
    <inertial>
      <origin xyz="0.0 -0.007 -0.0"/>
      <mass value="0.05"/>
      <inertia ixx="0.00001" ixy="0" ixz="0" iyy="0.000018" iyz="0" izz="0.00001"/>
    </inertial>
  </link>
  <joint name="rfr_wheel_joint" type="continuous">
    <origin rpy="0 0 3.14159274" xyz="-0.0004 0.07 0.118"/>
    <parent link="rear_right_steering_link"/>
    <child link="rfr_wheel_link"/>
    <limit effort="1.5" velocity="20"/>
    <axis xyz="0 1 0"/>
  </joint>
  <link name="rfr_wheel_link">
    <visual>
      <geometry>
        <mesh filename="package://h500_description/meshes/STL/wheel/H500_wheel.stl"/>
      </geometry>
    </visual>
    <collision>
      <geometry>
        <mesh filename="package://h500_description/meshes/STL/wheel/H500_wheel.stl"/>
      </geometry>
    </collision>
    <inertial>
      <origin xyz="0.0 -0.007 -0.0"/>
      <mass value="0.05"/>
      <inertia ixx="0.00001" ixy="0" ixz="0" iyy="0.000018" iyz="0" izz="0.00001"/>
    </inertial>
  </link>
  <joint name="rfl_wheel_joint" type="continuous">
    <origin rpy="0 0 3.14159274" xyz="-0.0004 -0.32 0.118"/>
    <parent link="rear_left_steering_link"/>
    <child link="rfl_wheel_link"/>
    <limit effort="1.5" velocity="20"/>
    <axis xyz="0 -1 0"/>
  </joint>
  <link name="rfl_wheel_link">
    <visual>
      <geometry>
        <mesh filename="package://h500_description/meshes/STL/wheel/H500_wheel.stl"/>
      </geometry>
    </visual>
    <collision>
      <geometry>
        <mesh filename="package://h500_description/meshes/STL/wheel/H500_wheel.stl"/>
      </geometry>
    </collision>
    <inertial>
      <origin xyz="0.0 -0.007 -0.0"/>
      <mass value="0.05"/>
      <inertia ixx="0.00001" ixy="0" ixz="0" iyy="0.000018" iyz="0" izz="0.00001"/>
    </inertial>
  </link>
  <transmission name="ffr_wheel_trans">
    <type>transmission_interface/SimpleTransmission</type>
    <joint name="ffr_wheel_joint">
      <hardwareInterface>hardware_interface/VelocityJointInterface</hardwareInterface>
    </joint>
    <actuator name="ffr_wheel_motor">
      <hardwareInterface>hardware_interface/VelocityJointInterface</hardwareInterface>
      <mechanicalReduction>1</mechanicalReduction>
    </actuator>
  </transmission>
  <transmission name="ffl_wheel_trans">
    <type>transmission_interface/SimpleTransmission</type>
    <joint name="ffl_wheel_joint">
      <hardwareInterface>hardware_interface/VelocityJointInterface</hardwareInterface>
    </joint>
    <actuator name="ffl_wheel_motor">
      <hardwareInterface>hardware_interface/VelocityJointInterface</hardwareInterface>
      <mechanicalReduction>1</mechanicalReduction>
    </actuator>
  </transmission>
  <transmission name="rfr_wheel_trans">
    <type>transmission_interface/SimpleTransmission</type>
    <joint name="rfr_wheel_joint">
      <hardwareInterface>hardware_interface/VelocityJointInterface</hardwareInterface>
    </joint>
    <actuator name="rfr_wheel_motor">
      <hardwareInterface>hardware_interface/VelocityJointInterface</hardwareInterface>
      <mechanicalReduction>1</mechanicalReduction>
    </actuator>
  </transmission>
  <transmission name="rfl_wheel_trans">
    <type>transmission_interface/SimpleTransmission</type>
    <joint name="rfl_wheel_joint">
      <hardwareInterface>hardware_interface/VelocityJointInterface</hardwareInterface>
    </joint>
    <actuator name="rfl_wheel_motor">
      <hardwareInterface>hardware_interface/VelocityJointInterface</hardwareInterface>
      <mechanicalReduction>1</mechanicalReduction>
    </actuator>
  </transmission>
  <transmission name="front_right_steering_trans">
    <type>transmission_interface/SimpleTransmission</type>
    <joint name="front_right_steering_joint">
      <hardwareInterface>hardware_interface/PositionJointInterface</hardwareInterface>
    </joint>
    <actuator name="front_right_steering_motor">
      <hardwareInterface>hardware_interface/PositionJointInterface</hardwareInterface>
      <mechanicalReduction>30</mechanicalReduction>
    </actuator>
  </transmission>
  <transmission name="front_left_steering_trans">
    <type>transmission_interface/SimpleTransmission</type>
    <joint name="front_left_steering_joint">
      <hardwareInterface>hardware_interface/PositionJointInterface</hardwareInterface>
    </joint>
    <actuator name="front_left_steering_motor">
      <hardwareInterface>hardware_interface/PositionJointInterface</hardwareInterface>
      <mechanicalReduction>30</mechanicalReduction>
    </actuator>
  </transmission>
  <transmission name="rear_right_steering_trans">
    <type>transmission_interface/SimpleTransmission</type>
    <joint name="rear_right_steering_joint">
      <hardwareInterface>hardware_interface/PositionJointInterface</hardwareInterface>
    </joint>
    <actuator name="rear_right_steering_motor">
      <hardwareInterface>hardware_interface/PositionJointInterface</hardwareInterface>
      <mechanicalReduction>30</mechanicalReduction>
    </actuator>
  </transmission>
  <transmission name="rear_left_steering_trans">
    <type>transmission_interface/SimpleTransmission</type>
    <joint name="rear_left_steering_joint">
      <hardwareInterface>hardware_interface/PositionJointInterface</hardwareInterface>
    </joint>
    <actuator name="rear_left_steering_motor">
      <hardwareInterface>hardware_interface/PositionJointInterface</hardwareInterface>
      <mechanicalReduction>30</mechanicalReduction>
    </actuator>
  </transmission>
  <!-- =============== Gazebo =============== -->
  <!-- original -->
  <!-- ->
  <gazebo>
    <plugin filename="libgazebo_ros_control.so" name="gazebo_ros_control">
    </plugin>
  </gazebo> -->

  <!-- edited on 18 dec 2023 -->
  <!-- Gazebo plugin -->
  <gazebo>
    <!-- Load ros_control plugin using the steer_bot_hardware_gazebo
    implementation of the hardware_interface::RobotHW -->
    <plugin name="gazebo_ros_control" filename="libgazebo_ros_control.so">
      <robotNamespace>${robot_namespace}</robotNamespace>
      <robotSimType>steer_bot_hardware_gazebo/SteerBotHardwareGazebo</robotSimType>
      <legacyModeNS>false</legacyModeNS>
    </plugin>
  </gazebo>

  <gazebo reference="robot_base">
    <selfCollide>false</selfCollide>
    <mu1 value="0.05"/>
    <mu2 value="0.05"/>
  </gazebo>
  <gazebo reference="fr_wheel_link">
    <selfCollide>false</selfCollide>
    <mu1 value="1.2"/>
    <mu2 value="1.2"/>
  </gazebo>
  <gazebo reference="fl_wheel_link">
    <selfCollide>false</selfCollide>
    <mu1 value="1.2"/>
    <mu2 value="1.2"/>
  </gazebo>
  <gazebo reference="rr_wheel_link">
    <selfCollide>false</selfCollide>
    <mu1 value="1.2"/>
    <mu2 value="1.2"/>
  </gazebo>
  <gazebo reference="rl_wheel_link">
    <selfCollide>false</selfCollide>
    <mu1 value="1.2"/>
    <mu2 value="1.2"/>
  </gazebo>
  <gazebo reference="front_right_steering_link">
    <selfCollide>false</selfCollide>
    <mu1 value="0.05"/>
    <mu2 value="0.05"/>
  </gazebo>
  <gazebo reference="front_left_steering_link">
    <selfCollide>false</selfCollide>
    <mu1 value="0.05"/>
    <mu2 value="0.05"/>
  </gazebo>
  <gazebo reference="rear_right_steering_link">
    <selfCollide>false</selfCollide>
    <mu1 value="0.05"/>
    <mu2 value="0.05"/>
  </gazebo>
  <gazebo reference="rear_left_steering_link">
    <selfCollide>false</selfCollide>
    <mu1 value="0.05"/>
    <mu2 value="0.05"/>
  </gazebo>

  <!-- edited on 18 dec 2023-->
  <!-- add robot base 3 and xacro property-->
  <!-- Math constants -->

</robot>
