<?xml version="1.0" encoding="utf-8"?>

<robot name="bunker_realsense_description">
  <material name="aluminum">
    <color rgba="0.5 0.5 0.5 1"/>
  </material>
  <material name="plastic">
    <color rgba="0.1 0.1 0.1 1"/>
  </material>
  <link name="base_link"/>
  <!-- camera body, with origin at bottom screw mount -->
  <joint name="camera_joint" type="fixed">
    <origin rpy="0 0 0" xyz="0 0 0"/>
    <parent link="base_link"/>
    <child link="camera_bottom_screw_frame"/>
  </joint>
  <link name="camera_bottom_screw_frame"/>
  <joint name="camera_link_joint" type="fixed">
    <origin rpy="0 0 0" xyz="0.0106 0.0175 0.0125"/>
    <parent link="camera_bottom_screw_frame"/>
    <child link="camera_link"/>
  </joint>
  <link name="camera_link">
    <visual>
      <!-- the mesh origin is at front plate in between the two infrared camera axes -->
      <origin rpy="1.57079632679 0 1.57079632679" xyz="0.0043 -0.0175 0"/>
      <geometry>
        <mesh filename="package://realsense2_description/meshes/d435.dae"/>
      </geometry>
    </visual>
    <collision>
      <origin rpy="0 0 0" xyz="0 -0.0175 0"/>
      <geometry>
        <box size="0.02505 0.09 0.025"/>
      </geometry>
    </collision>
    <inertial>
      <!-- The following are not reliable values, and should not be used for modeling -->
      <mass value="0.072"/>
      <origin xyz="0 0 0"/>
      <inertia ixx="0.003881243" ixy="0.0" ixz="0.0" iyy="0.000498940" iyz="0.0" izz="0.003879257"/>
    </inertial>
  </link>
  <!-- camera depth joints and links -->
  <joint name="camera_depth_joint" type="fixed">
    <origin rpy="0 0 0" xyz="0 0 0"/>
    <parent link="camera_link"/>
    <child link="camera_depth_frame"/>
  </joint>
  <link name="camera_depth_frame"/>
  <joint name="camera_depth_optical_joint" type="fixed">
    <origin rpy="-1.57079632679 0 -1.57079632679" xyz="0 0 0"/>
    <parent link="camera_depth_frame"/>
    <child link="camera_depth_optical_frame"/>
  </joint>
  <link name="camera_depth_optical_frame"/>
  <!-- camera left IR joints and links -->
  <joint name="camera_infra1_joint" type="fixed">
    <origin rpy="0 0 0" xyz="0 0.0 0"/>
    <parent link="camera_link"/>
    <child link="camera_infra1_frame"/>
  </joint>
  <link name="camera_infra1_frame"/>
  <joint name="camera_infra1_optical_joint" type="fixed">
    <origin rpy="-1.57079632679 0 -1.57079632679" xyz="0 0 0"/>
    <parent link="camera_infra1_frame"/>
    <child link="camera_infra1_optical_frame"/>
  </joint>
  <link name="camera_infra1_optical_frame"/>
  <!-- camera right IR joints and links -->
  <joint name="camera_infra2_joint" type="fixed">
    <origin rpy="0 0 0" xyz="0 -0.05 0"/>
    <parent link="camera_link"/>
    <child link="camera_infra2_frame"/>
  </joint>
  <link name="camera_infra2_frame"/>
  <joint name="camera_infra2_optical_joint" type="fixed">
    <origin rpy="-1.57079632679 0 -1.57079632679" xyz="0 0 0"/>
    <parent link="camera_infra2_frame"/>
    <child link="camera_infra2_optical_frame"/>
  </joint>
  <link name="camera_infra2_optical_frame"/>
  <!-- camera color joints and links -->
  <joint name="camera_color_joint" type="fixed">
    <origin rpy="0 0 0" xyz="0 0.015 0"/>
    <parent link="camera_link"/>
    <child link="camera_color_frame"/>
  </joint>
  <link name="camera_color_frame"/>
  <joint name="camera_color_optical_joint" type="fixed">
    <origin rpy="-1.57079632679 0 -1.57079632679" xyz="0 0 0"/>
    <parent link="camera_color_frame"/>
    <child link="camera_color_optical_frame"/>
  </joint>
  <link name="camera_color_optical_frame"/>
  <material name="blue">
    <color rgba="0 0 0.8 1"/>
  </material>
  <material name="red">
    <color rgba="1 0 0 1"/>
  </material>
  <material name="white">
    <color rgba="1 1 1 1"/>
  </material>
  <!--<link name="rbot_base">
    <visual>
      <geometry>
        <box size="0.045 0.09 0.03"/>
      </geometry>
      <origin rpy="0 0 0" xyz="0 0 0"/>
      <material name="blue"/>
    </visual>
  </link>
  <link name="servo_bottom">
    <visual>
      <geometry>
        <cylinder length="0.05" radius="0.015"/>
      </geometry>
      <origin rpy="0 0 0" xyz="0 0 0"/>
      <material name="red"/>
    </visual>
  </link>
  <link name="U_Link">
    <visual>
      <geometry>
        <box size="0.015 0.03 0.064"/>
      </geometry>
      <origin rpy="0 0 0" xyz="0 0 0"/>
      <material name="blue"/>
    </visual>
  </link>
  <link name="servo_mid">
    <visual>
      <geometry>
        <cylinder length="0.05" radius="0.015"/>
      </geometry>
      <origin rpy="1.57 0 0" xyz="0 0 0"/>
      <material name="red"/>
    </visual>
  </link>
  <link name="servo_up">
    <visual>
      <geometry>
        <cylinder length="0.05" radius="0.015"/>
      </geometry>
      <origin rpy="0 0 0" xyz="0 0 0"/>
      <material name="red"/>
    </visual>
  </link>
  <link name="up_mount">
    <visual>
      <geometry>
        <box size="0.05 0.148 0.05"/>
      </geometry>
      <origin rpy="0 0.785 0" xyz="0 0 0"/>
      <material name="white"/>
    </visual>
  </link> -->
    
  <link name="rbot_base2">
    <visual>
      <geometry>
        <box size="0.045 0.09 0.03"/>
      </geometry>
      <origin rpy="0 0 0" xyz="0 0 0"/>
      <material name="red"/>
    </visual>
  </link>
  <link name="servo_bottom2">
    <visual>
      <geometry>
        <cylinder length="0.25" radius="0.015"/>
      </geometry>
      <origin rpy="0 0 0" xyz="0 0 0"/>
      <material name="green"/>
    </visual>
  </link> 

  <link name="up_mount2">
    <visual>
      <geometry>
        <box size="0.05 0.148 0.05"/>
      </geometry>
      <origin rpy="0 0. 0" xyz="0 0 0"/>
      <material name="blue"/>
    </visual>
  </link> --> 
    
    <!-- added new joint-->
 <!--<joint name="base_to_Servo_B2" type="fixed">
    <parent link="rbot_base2"/>
    <child link="servo_bottom2"/>
    <origin xyz="0 0 0.04"/>
 <joint name="servo_bottom_to_up_mount2" type="revolute">
    <parent link="servo_bottom2"/>
    <child link="up_mount2"/>
    <axis xyz="0 0 1"/>
    <limit effort="1000.0" lower="-1.57" upper="1.57" velocity="0.5"/>
    <origin xyz="-0.0237 -0.009 0.04"/>
  </joint>
  <joint name="mount_to_camera2" type="fixed">
    <parent link="up_mount2"/>
    <child link="base_link"/>
    <origin rpy="0 -0.785 0" xyz="0.03 0 0.02"/> -->
 <joint name="base_to_Servo_B2" type="fixed">
    <parent link="rbot_base2"/>
    <child link="servo_bottom2"/>
    <origin xyz="0 0 0.14"/>
  </joint>
 <joint name="servo_bottom_to_up_mount2" type="fixed">
    <parent link="servo_bottom2"/>
    <child link="up_mount2"/>
    <origin xyz="0 0 0.15"/>
  </joint>
  <joint name="mount_to_camera2" type="fixed">
    <parent link="up_mount2"/>
    <child link="base_link"/>
    <origin rpy="0 0 0" xyz="0.03 0 0.001"/>
  </joint>
    
    
<!--  <joint name="base_to_Servo_B" type="fixed">
    <parent link="rbot_base"/>
    <child link="servo_bottom"/>
    <origin xyz="0 0 0.0"/>
  </joint>
  <joint name="Joint_1" type="revolute">
    <parent link="servo_bottom"/>
    <child link="U_Link"/>
    <axis xyz="0 0 1"/>
    <limit effort="1000.0" lower="-1.57" upper="1.57" velocity="0.5"/>
    <origin xyz="0 0 0.056"/>
  </joint>
  <joint name="Joint_2" type="revolute">
    <parent link="U_Link"/>
    <child link="servo_mid"/>
    <axis xyz="0 1 0"/>
    <limit effort="1000.0" lower="-1.57" upper="1.57" velocity="0.5"/>
    <origin rpy="0 0.67 0" xyz="0 0 0.036"/>
  </joint>
  <joint name="servo_mid_to_servo_up" type="fixed">
    <parent link="servo_mid"/>
    <child link="servo_up"/>
    <origin xyz="-0.0237 -0.009 0"/>
  </joint>
  <joint name="Joint_3" type="revolute">
    <parent link="servo_up"/>
    <child link="up_mount"/>
    <axis xyz="0 0 1"/>
    <limit effort="1000.0" lower="-1.57" upper="1.57" velocity="0.5"/>
    <origin xyz="-0.0237 -0.009 0.04"/>
  </joint>
  <joint name="mount_to_camera" type="fixed">
    <parent link="up_mount"/>
    <child link="base_link2"/>
    <origin rpy="0 -0.785 0" xyz="0.03 0 0.02"/>
  </joint> -->
  <material name="invisible">
    <color rgba="0 0 0 0"/>
  </material>
  <material name="green">
    <color rgba="0 1 0 1"/>
  </material>
  <material name="grey">
    <color rgba="0.9 0.9 0.9 1"/>
  </material>
  <link name="base_footprint"/>
  <link name="robot_base">
    <inertial>
      <origin rpy="0 0 0" xyz="0.0212410555532523 0.00475458359568469 -0.127580557949736"/>
      <mass value="22"/>
      <inertia ixx="0.607716166684979" ixy="1.92178193996147E-05" ixz="-0.036532069356182" iyy="1.70041426855404" iyz="2.16963122007266E-05" izz="1.84232351935185"/>
    </inertial>
    <visual>
      <origin rpy="1.57 0 3.14" xyz="0.53 -0.392 -0.358"/>
      <geometry>
        <mesh filename="package://bunker_description/meshes/BUNKER.STL" scale="0.001 0.001 0.001"/>
      </geometry>
      <material name="">
        <color rgba="0.5 0.5 0.5  1"/>
      </material>
    </visual>
    <collision>
      <origin rpy="1.57 0 3.14" xyz="0.53 -0.392 -0.358"/>
      <geometry>
        <mesh filename="package://bunker_description/meshes/BUNKER.STL" scale="0.001 0.001 0.001"/>
      </geometry>
    </collision>
  </link>
   
  <link name="imu_link">
    <visual>
      <geometry>
        <box size="0.05 0.026 0.05"/>
      </geometry>
      <material name="green"/>
    </visual>
  </link>
    
  <joint name="imu_joint" type="fixed">
    <origin rpy="0 0 0" xyz="0.0 0.0 0.28"/>
    <parent link="rbot_base2"/>
    <child link="imu_link"/>
  </joint>  
    
  <link name="wheel1_Link">
    <inertial>
      <origin rpy="0 0 0" xyz="0 -1.38777878078145E-17 -0.0719999999999999"/>
      <mass value="0.392034219968119"/>
      <inertia ixx="0.000378440530116381" ixy="5.60822736805661E-21" ixz="3.04207802822425E-20" iyy="0.000378440530116381" iyz="-7.56626980356474E-21" izz="0.000710150518820894"/>
    </inertial>
    <visual>
      <origin rpy="0 0 0" xyz="0 0 0"/>
      <geometry>
        <mesh filename="package://bunker_description/meshes/wheel1_Link.STL"/>
      </geometry>
      <material name="">
        <color rgba="1 1 1 1"/>
      </material>
    </visual>
    <collision>
      <origin rpy="0 0 0" xyz="0 0 0"/>
      <geometry>
        <mesh filename="package://bunker_description/meshes/wheel1_Link.STL"/>
      </geometry>
    </collision>
  </link>
  <joint name="base_joint" type="fixed">
    <origin rpy="0 0 0" xyz="0 0 0.355"/>
    <parent link="base_footprint"/>
    <child link="robot_base"/>
  </joint>
    
  <joint name="baseto_framestand" type="fixed">
    <origin rpy="0 0 0" xyz="0.3 0 0"/>
    <parent link="robot_base"/>
    <child link="rbot_base2"/>
  </joint>
    
  <joint name="wheel1_joint" type="revolute">
    <origin rpy="1.5708 0 -3.1416" xyz="0.44403 0.3495 -0.12853"/>
    <parent link="robot_base"/>
    <child link="wheel1_Link"/>
    <axis xyz="0 0 1"/>
    <limit effort="0" lower="-180" upper="180" velocity="0"/>
  </joint>
  <link name="wheel1.1_Link">
    <inertial>
      <origin rpy="0 0 0" xyz="-1.74279013442913E-08 5.87093572021469E-08 -0.0720000000000001"/>
      <mass value="0.190328287901002"/>
      <inertia ixx="6.58750963981394E-05" ixy="-1.46558944641469E-09" ixz="-8.34967331718859E-12" iyy="6.58795984671517E-05" iyz="-2.4786046130206E-12" izz="0.000112721820875598"/>
    </inertial>
    <visual>
      <origin rpy="0 0 0" xyz="0 0 0"/>
      <geometry>
        <mesh filename="package://bunker_description/meshes/wheel1.1_Link.STL"/>
      </geometry>
      <material name="">
        <color rgba="1 1 1 1"/>
      </material>
    </visual>
    <collision>
      <origin rpy="0 0 0" xyz="0 0 0"/>
      <geometry>
        <mesh filename="package://bunker_description/meshes/wheel1.1_Link.STL"/>
      </geometry>
    </collision>
  </link>
  <joint name="wheel1.1_jont" type="revolute">
    <origin rpy="1.5708 0 -3.1416" xyz="0.37551 0.3495 -0.22305"/>
    <parent link="robot_base"/>
    <child link="wheel1.1_Link"/>
    <axis xyz="0 0 1"/>
    <limit effort="0" lower="-180" upper="180" velocity="0"/>
  </joint>
  <link name="wheel1.2_Link">
    <inertial>
      <origin rpy="0 0 0" xyz="1.66533453693773E-16 4.16333634234434E-17 -0.0720000000000002"/>
      <mass value="0.271192811687251"/>
      <inertia ixx="0.000179574259018481" ixy="1.15789498120549E-20" ixz="1.3563351843978E-21" iyy="0.000179574259018481" iyz="6.0369822309622E-23" izz="0.000332594534732139"/>
    </inertial>
    <visual>
      <origin rpy="0 0 0" xyz="0 0 0"/>
      <geometry>
        <mesh filename="package://bunker_description/meshes/wheel1.2_Link.STL"/>
      </geometry>
      <material name="">
        <color rgba="1 1 1 1"/>
      </material>
    </visual>
    <collision>
      <origin rpy="0 0 0" xyz="0 0 0"/>
      <geometry>
        <mesh filename="package://bunker_description/meshes/wheel1.2_Link.STL"/>
      </geometry>
    </collision>
  </link>
  <joint name="wheel1.2_joint" type="revolute">
    <origin rpy="1.5708 0 -3.1416" xyz="0.29039 0.3495 -0.28104"/>
    <parent link="robot_base"/>
    <child link="wheel1.2_Link"/>
    <axis xyz="0 0 1"/>
    <limit effort="0" lower="-180" upper="180" velocity="0"/>
  </joint>
  <link name="wheel1.3_Link">
    <inertial>
      <origin rpy="0 0 0" xyz="3.44025652177504E-05 -2.66346274915008E-05 -0.0701504149473696"/>
      <mass value="0.245835028330933"/>
      <inertia ixx="0.000105254202004996" ixy="1.32328029886322E-08" ixz="3.84294589102693E-11" iyy="0.000105248656147198" iyz="-1.41155611914915E-11" izz="0.000173280771745758"/>
    </inertial>
    <visual>
      <origin rpy="0 0 0" xyz="0 0 0"/>
      <geometry>
        <mesh filename="package://bunker_description/meshes/wheel1.3_Link.STL"/>
      </geometry>
      <material name="">
        <color rgba="1 1 1 1"/>
      </material>
    </visual>
    <collision>
      <origin rpy="0 0 0" xyz="0 0 0"/>
      <geometry>
        <mesh filename="package://bunker_description/meshes/wheel1.3_Link.STL"/>
      </geometry>
    </collision>
  </link>
  <joint name="wheel1.3_joint" type="revolute">
    <origin rpy="1.5708 0 -3.1416" xyz="0.29603 0.3495 -0.087"/>
    <parent link="robot_base"/>
    <child link="wheel1.3_Link"/>
    <axis xyz="0 0 -1"/>
    <limit effort="0" lower="-180" upper="180" velocity="0"/>
  </joint>
  <link name="wheel2_Link">
    <inertial>
      <origin rpy="0 0 0" xyz="-1.66533453693773E-16 0 0.072"/>
      <mass value="0.392034219968119"/>
      <inertia ixx="0.000378440530116381" ixy="3.37302217863781E-21" ixz="2.71827270955143E-20" iyy="0.000378440530116381" iyz="-7.32821644893157E-21" izz="0.000710150518820894"/>
    </inertial>
    <visual>
      <origin rpy="0 0 0" xyz="0 0 0"/>
      <geometry>
        <mesh filename="package://bunker_description/meshes/wheel2_Link.STL"/>
      </geometry>
      <material name="">
        <color rgba="1 1 1 1"/>
      </material>
    </visual>
    <collision>
      <origin rpy="0 0 0" xyz="0 0 0"/>
      <geometry>
        <mesh filename="package://bunker_description/meshes/wheel2_Link.STL"/>
      </geometry>
    </collision>
  </link>
  <joint name="wheel2_joint" type="revolute">
    <origin rpy="1.5708 0 -3.1416" xyz="0.44403 -0.3495 -0.12853"/>
    <parent link="robot_base"/>
    <child link="wheel2_Link"/>
    <axis xyz="0 0 -1"/>
    <limit effort="0" lower="-180" upper="180" velocity="0"/>
  </joint>
  <link name="wheel2.1_Link">
    <inertial>
      <origin rpy="0 0 0" xyz="-1.74279017328693E-08 5.87093572160247E-08 0.0720000000000002"/>
      <mass value="0.190328287901002"/>
      <inertia ixx="6.58750963981394E-05" ixy="-1.46558944642761E-09" ixz="-8.34967332343028E-12" iyy="6.58795984671517E-05" iyz="-2.47860459929511E-12" izz="0.000112721820875598"/>
    </inertial>
    <visual>
      <origin rpy="0 0 0" xyz="0 0 0"/>
      <geometry>
        <mesh filename="package://bunker_description/meshes/wheel2.1_Link.STL"/>
      </geometry>
      <material name="">
        <color rgba="1 1 1 1"/>
      </material>
    </visual>
    <collision>
      <origin rpy="0 0 0" xyz="0 0 0"/>
      <geometry>
        <mesh filename="package://bunker_description/meshes/wheel2.1_Link.STL"/>
      </geometry>
    </collision>
  </link>
  <joint name="wheel2.1_joint" type="revolute">
    <origin rpy="1.5708 0 -3.1416" xyz="0.37551 -0.3495 -0.22305"/>
    <parent link="robot_base"/>
    <child link="wheel2.1_Link"/>
    <axis xyz="0 0 -1"/>
    <limit effort="0" lower="-180" upper="180" velocity="0"/>
  </joint>
  <link name="wheel2.2_Link">
    <inertial>
      <origin rpy="0 0 0" xyz="-1.38777878078145E-16 -4.85722573273506E-17 0.0720000000000003"/>
      <mass value="0.27119281168725"/>
      <inertia ixx="0.00017957425901848" ixy="6.28960386226657E-21" ixz="2.14010788664762E-21" iyy="0.00017957425901848" iyz="1.27709655724716E-22" izz="0.000332594534732139"/>
    </inertial>
    <visual>
      <origin rpy="0 0 0" xyz="0 0 0"/>
      <geometry>
        <mesh filename="package://bunker_description/meshes/wheel2.2_Link.STL"/>
      </geometry>
      <material name="">
        <color rgba="1 1 1 1"/>
      </material>
    </visual>
    <collision>
      <origin rpy="0 0 0" xyz="0 0 0"/>
      <geometry>
        <mesh filename="package://bunker_description/meshes/wheel2.2_Link.STL"/>
      </geometry>
    </collision>
  </link>
  <joint name="wheel2.2_joint" type="revolute">
    <origin rpy="1.5708 0 -3.1416" xyz="0.29039 -0.3495 -0.28104"/>
    <parent link="robot_base"/>
    <child link="wheel2.2_Link"/>
    <axis xyz="0 0 -1"/>
    <limit effort="0" lower="-180" upper="180" velocity="0"/>
  </joint>
  <link name="wheel2.3_Link">
    <inertial>
      <origin rpy="0 0 0" xyz="3.51083051564616E-05 -2.7181014665284E-05 0.0709276770204769"/>
      <mass value="0.240893303086836"/>
      <inertia ixx="0.000105035118852508" ixy="1.32328029886296E-08" ixz="3.84294589110161E-11" iyy="0.00010502957299471" iyz="-1.41155611875745E-11" izz="0.00017298179736849"/>
    </inertial>
    <visual>
      <origin rpy="0 0 0" xyz="0 0 0"/>
      <geometry>
        <mesh filename="package://bunker_description/meshes/wheel2.3_Link.STL"/>
      </geometry>
      <material name="">
        <color rgba="1 1 1 1"/>
      </material>
    </visual>
    <collision>
      <origin rpy="0 0 0" xyz="0 0 0"/>
      <geometry>
        <mesh filename="package://bunker_description/meshes/wheel2.3_Link.STL"/>
      </geometry>
    </collision>
  </link>
  <joint name="wheel2.3_joint" type="revolute">
    <origin rpy="1.5708 0 -3.1416" xyz="0.29603 -0.3495 -0.087"/>
    <parent link="robot_base"/>
    <child link="wheel2.3_Link"/>
    <axis xyz="0 0 1"/>
    <limit effort="0" lower="-180" upper="180" velocity="0"/>
  </joint>
  <link name="wheel3_Link">
    <inertial>
      <origin rpy="0 0 0" xyz="-1.5143569731535E-10 7.07767178198537E-16 -0.0246054820762604"/>
      <mass value="1.35828296445862"/>
      <inertia ixx="0.00232456013775523" ixy="-1.61343020248111E-09" ixz="-4.5670735364335E-13" iyy="0.00232456564213727" iyz="-1.36036258272812E-18" izz="0.00308347787030649"/>
    </inertial>
    <visual>
      <origin rpy="0 0 0" xyz="0 0 0"/>
      <geometry>
        <mesh filename="package://bunker_description/meshes/wheel3_Link.STL"/>
      </geometry>
      <material name="">
        <color rgba="1 1 1 1"/>
      </material>
    </visual>
    <collision>
      <origin rpy="0 0 0" xyz="0 0 0"/>
      <geometry>
        <mesh filename="package://bunker_description/meshes/wheel3_Link.STL"/>
      </geometry>
    </collision>
  </link>
  <joint name="wheel3_joint" type="revolute">
    <origin rpy="1.5708 0 -3.1416" xyz="-0.38871 0.295 -0.19381"/>
    <parent link="robot_base"/>
    <child link="wheel3_Link"/>
    <axis xyz="0 0 -1"/>
    <limit effort="0" lower="-180" upper="180" velocity="0"/>
  </joint>
  <link name="wheel3.1_Link">
    <inertial>
      <origin rpy="0 0 0" xyz="5.55111512312578E-17 5.55111512312578E-17 -0.0720000000000002"/>
      <mass value="0.271192811687251"/>
      <inertia ixx="0.000179574259018481" ixy="-1.73824343982442E-20" ixz="-2.53159654382751E-21" iyy="0.000179574259018481" iyz="-3.13741449878515E-21" izz="0.000332594534732139"/>
    </inertial>
    <visual>
      <origin rpy="0 0 0" xyz="0 0 0"/>
      <geometry>
        <mesh filename="package://bunker_description/meshes/wheel3.1_Link.STL"/>
      </geometry>
      <material name="">
        <color rgba="1 1 1 1"/>
      </material>
    </visual>
    <collision>
      <origin rpy="0 0 0" xyz="0 0 0"/>
      <geometry>
        <mesh filename="package://bunker_description/meshes/wheel3.1_Link.STL"/>
      </geometry>
    </collision>
  </link>
  <joint name="wheel3.1_joint" type="revolute">
    <origin rpy="1.5708 0 -3.1416" xyz="-0.23111 0.3495 -0.27671"/>
    <parent link="robot_base"/>
    <child link="wheel3.1_Link"/>
    <axis xyz="0 0 1"/>
    <limit effort="0" lower="-180" upper="180" velocity="0"/>
  </joint>
  <link name="wheel3.2_Link">
    <inertial>
      <origin rpy="0 0 0" xyz="7.58128369110489E-17 7.63278329429795E-17 -0.0720000000000003"/>
      <mass value="0.27119281168725"/>
      <inertia ixx="0.00017957425901848" ixy="9.82929052458426E-22" ixz="1.10990388135291E-21" iyy="0.00017957425901848" iyz="-4.81322327079121E-21" izz="0.000332594534732139"/>
    </inertial>
    <visual>
      <origin rpy="0 0 0" xyz="0 0 0"/>
      <geometry>
        <mesh filename="package://bunker_description/meshes/wheel3.2_Link.STL"/>
      </geometry>
      <material name="">
        <color rgba="1 1 1 1"/>
      </material>
    </visual>
    <collision>
      <origin rpy="0 0 0" xyz="0 0 0"/>
      <geometry>
        <mesh filename="package://bunker_description/meshes/wheel3.2_Link.STL"/>
      </geometry>
    </collision>
  </link>
  <joint name="wheel3.2_joint" type="revolute">
    <origin rpy="1.5708 0 -3.1416" xyz="0.043885 0.3495 -0.27671"/>
    <parent link="robot_base"/>
    <child link="wheel3.2_Link"/>
    <axis xyz="0 0 1"/>
    <limit effort="0" lower="-180" upper="180" velocity="0"/>
  </joint>
  <link name="wheel3.3_Link">
    <inertial>
      <origin rpy="0 0 0" xyz="1.37732703020532E-08 -5.29206664124648E-05 -0.0701501700151683"/>
      <mass value="0.245836054976119"/>
      <inertia ixx="0.000105264944409738" ixy="7.98231761628902E-12" ixz="6.80400273605472E-11" iyy="0.000105238344260685" iyz="-2.72106317781962E-11" izz="0.000173281039335396"/>
    </inertial>
    <visual>
      <origin rpy="0 0 0" xyz="0 0 0"/>
      <geometry>
        <mesh filename="package://bunker_description/meshes/wheel3.3_Link.STL"/>
      </geometry>
      <material name="">
        <color rgba="1 1 1 1"/>
      </material>
    </visual>
    <collision>
      <origin rpy="0 0 0" xyz="0 0 0"/>
      <geometry>
        <mesh filename="package://bunker_description/meshes/wheel3.3_Link.STL"/>
      </geometry>
    </collision>
  </link>
  <joint name="wheel3.3_joint" type="revolute">
    <origin rpy="1.5708 0 -3.1416" xyz="-0.28597 0.3495 -0.087"/>
    <parent link="robot_base"/>
    <child link="wheel3.3_Link"/>
    <axis xyz="0 0 -1"/>
    <limit effort="0" lower="-180" upper="180" velocity="0"/>
  </joint>
  <link name="wheel4_Link">
    <inertial>
      <origin rpy="0 0 0" xyz="5.55111512312578E-17 1.51436273243544E-10 0.0245928853369881"/>
      <mass value="1.35828296445862"/>
      <inertia ixx="0.00232456564213727" ixy="-1.6134302023684E-09" ixz="-3.67391703208082E-19" iyy="0.00232456013775523" iyz="-4.56707494796216E-13" izz="0.00308347787030649"/>
    </inertial>
    <visual>
      <origin rpy="0 0 0" xyz="0 0 0"/>
      <geometry>
        <mesh filename="package://bunker_description/meshes/wheel4_Link.STL"/>
      </geometry>
      <material name="">
        <color rgba="1 1 1 1"/>
      </material>
    </visual>
    <collision>
      <origin rpy="0 0 0" xyz="0 0 0"/>
      <geometry>
        <mesh filename="package://bunker_description/meshes/wheel4_Link.STL"/>
      </geometry>
    </collision>
  </link>
  <joint name="wheel4_joint" type="revolute">
    <origin rpy="1.5708 0 -3.1416" xyz="-0.38871 -0.295 -0.19381"/>
    <parent link="robot_base"/>
    <child link="wheel4_Link"/>
    <axis xyz="0 0 1"/>
    <limit effort="0" lower="-180" upper="180" velocity="0"/>
  </joint>
  <link name="wheel4.1_Link">
    <inertial>
      <origin rpy="0 0 0" xyz="-1.11022302462516E-16 -5.55111512312578E-17 0.0720000000000002"/>
      <mass value="0.271192811687251"/>
      <inertia ixx="0.000179574259018481" ixy="-7.93399024302093E-21" ixz="-2.13342044570487E-21" iyy="0.000179574259018481" iyz="-3.23624373974149E-21" izz="0.000332594534732139"/>
    </inertial>
    <visual>
      <origin rpy="0 0 0" xyz="0 0 0"/>
      <geometry>
        <mesh filename="package://bunker_description/meshes/wheel4.1_Link.STL"/>
      </geometry>
      <material name="">
        <color rgba="1 1 1 1"/>
      </material>
    </visual>
    <collision>
      <origin rpy="0 0 0" xyz="0 0 0"/>
      <geometry>
        <mesh filename="package://bunker_description/meshes/wheel4.1_Link.STL"/>
      </geometry>
    </collision>
  </link>
  <joint name="wheel4.1_joint" type="revolute">
    <origin rpy="1.5708 0 -3.1416" xyz="-0.23111 -0.3495 -0.27671"/>
    <parent link="robot_base"/>
    <child link="wheel4.1_Link"/>
    <axis xyz="0 0 -1"/>
    <limit effort="0" lower="-180" upper="180" velocity="0"/>
  </joint>
  <link name="wheel4.2_Link">
    <inertial>
      <origin rpy="0 0 0" xyz="-7.64498056873841E-17 -4.85722573273506E-17 0.0720000000000004"/>
      <mass value="0.27119281168725"/>
      <inertia ixx="0.00017957425901848" ixy="6.3005828905746E-22" ixz="1.1753358195074E-22" iyy="0.00017957425901848" iyz="-3.27347099653111E-21" izz="0.000332594534732139"/>
    </inertial>
    <visual>
      <origin rpy="0 0 0" xyz="0 0 0"/>
      <geometry>
        <mesh filename="package://bunker_description/meshes/wheel4.2_Link.STL"/>
      </geometry>
      <material name="">
        <color rgba="1 1 1 1"/>
      </material>
    </visual>
    <collision>
      <origin rpy="0 0 0" xyz="0 0 0"/>
      <geometry>
        <mesh filename="package://bunker_description/meshes/wheel4.2_Link.STL"/>
      </geometry>
    </collision>
  </link>
  <joint name="wheel4.2_joint" type="revolute">
    <origin rpy="1.5708 0 -3.1416" xyz="0.043885 -0.3495 -0.27671"/>
    <parent link="robot_base"/>
    <child link="wheel4.2_Link"/>
    <axis xyz="0 0 -1"/>
    <limit effort="0" lower="-180" upper="180" velocity="0"/>
  </joint>
  <link name="wheel4.3_Link">
    <inertial>
      <origin rpy="0 0 0" xyz="1.37732700244975E-08 -5.29206664124926E-05 0.0701152686893121"/>
      <mass value="0.245836054976119"/>
      <inertia ixx="0.000105264944409738" ixy="7.98231761858719E-12" ixz="6.80400273764357E-11" iyy="0.000105238344260685" iyz="-2.72106317797361E-11" izz="0.000173281039335396"/>
    </inertial>
    <visual>
      <origin rpy="0 0 0" xyz="0 0 0"/>
      <geometry>
        <mesh filename="package://bunker_description/meshes/wheel4.3_Link.STL"/>
      </geometry>
      <material name="">
        <color rgba="1 1 1 1"/>
      </material>
    </visual>
    <collision>
      <origin rpy="0 0 0" xyz="0 0 0"/>
      <geometry>
        <mesh filename="package://bunker_description/meshes/wheel4.3_Link.STL"/>
      </geometry>
    </collision>
  </link>
  <joint name="wheel4.3_joint" type="revolute">
    <origin rpy="1.5708 0 -3.1416" xyz="-0.28597 -0.3495 -0.087"/>
    <parent link="robot_base"/>
    <child link="wheel4.3_Link"/>
    <axis xyz="0 0 1"/>
    <limit effort="0" lower="-180" upper="180" velocity="0"/>
  </joint>
  <!-- /////////////////////////////////   gazebo color   ////////////////////////////////////// -->
  <gazebo reference="robot_base">
    <material>Gazebo/Gray</material>
  </gazebo>
  <gazebo>
    <plugin filename="libgazebo_ros_planar_move.so" name="object_controller">
      <commandTopic>cmd_vel</commandTopic>
      <odometryTopic>odom</odometryTopic>
      <odometryFrame>odom</odometryFrame>
      <odometryRate>20.0</odometryRate>
      <robotBaseFrame>base_link</robotBaseFrame>
    </plugin>
  </gazebo>

  <gazebo>
    <plugin name="gps_controller" filename="libhector_gazebo_ros_gps.so">
      <!--<robotNamespace>$(arg robot_namespace)</robotNamespace> -->
      <updateRate>40</updateRate>
      <bodyName>robot_base</bodyName>
      <frameId>robot_base</frameId>
      <topicName>navsat/fix</topicName>
      <velocityTopicName>navsat/vel</velocityTopicName>
      <referenceLatitude>49.9</referenceLatitude>
      <referenceLongitude>8.9</referenceLongitude>
      <referenceHeading>0</referenceHeading>
      <referenceAltitude>0</referenceAltitude>
      <drift>0.0001 0.0001 0.0001</drift>
    </plugin>
  </gazebo>

</robot>

