<?xml version="1.0" encoding="utf-8"?>
<!-- =================================================================================== -->
<!-- |    This document was autogenerated by xacro from /home/andi/catkin_redevel_ws/src/hada_explorer_bot/hada_explorer_description/urdf/h500.urdf.xacro | -->
<!-- |    EDITING THIS FILE BY HAND IS NOT RECOMMENDED                                 | -->
<!-- =================================================================================== -->
<robot name="h500_sprayer">
  <!-- =============== Link & Joint =============== -->
  <!-- Base -->
  <link name="base_footprint"/>
  <joint name="base_link_joint" type="fixed">
    <origin rpy="0 0 0" xyz="0 0 0.05"/>
    <parent link="base_footprint"/>
    <child link="base_link"/>
  </joint>
  <link name="base_link">
    <visual>
      <geometry>
        <mesh filename="package://h500_description/meshes/DAE/base/h500_body.dae"/>
      </geometry>
    </visual>
    <collision>
      <geometry>
        <mesh filename="package://h500_description/meshes/DAE/base/h500_body.dae"/>
      </geometry>
    </collision>
    <inertial>
      <origin xyz="0 0 0.017"/>
      <mass value="1.2"/>
      <inertia ixx="0.0001873" ixy="0" ixz="0" iyy="0.000055" iyz="0" izz="0.0002283"/>
    </inertial>
  </link>
  <joint name="front_right_steering_joint" type="revolute">
    <origin xyz="-0.442 0.361 0.0135"/>
    <parent link="base_link"/>
    <child link="front_right_steering_link"/>
    <limit effort="5" lower="-2.1" upper="2.1" velocity="6.28"/>
    <axis xyz="0 0 2."/>
  </joint>
  <link name="front_right_steering_link">
    <visual>
      <geometry>
        <mesh filename="package://h500_description/meshes/DAE/suspension/front_right_link.dae"/>
      </geometry>
    </visual>
    <collision>
      <geometry>
        <mesh filename="package://h500_description/meshes/DAE/suspension/front_right_link.dae"/>
      </geometry>
    </collision>
    <inertial>
      <origin xyz="0 0 -0.02"/>
      <mass value="0.15"/>
      <inertia ixx="0.00001" ixy="0" ixz="0" iyy="0.00001" iyz="0" izz="0.000004"/>
    </inertial>
  </link>
  <joint name="front_left_steering_joint" type="revolute">
    <origin xyz="-0.442 -0.3495 0.0135"/>
    <parent link="base_link"/>
    <child link="front_left_steering_link"/>
    <limit effort="5" lower="-2.1" upper="2.1" velocity="6.28"/>
    <axis xyz="0 0 1"/>
  </joint>
  <link name="front_left_steering_link">
    <visual>
      <geometry>
        <mesh filename="package://h500_description/meshes/DAE/suspension/front_left_link.dae"/>
      </geometry>
    </visual>
    <collision>
      <geometry>
        <mesh filename="package://h500_description/meshes/DAE/suspension/front_left_link.dae"/>
      </geometry>
    </collision>
    <inertial>
      <origin xyz="0 0 -0.02"/>
      <mass value="0.15"/>
      <inertia ixx="0.00001" ixy="0" ixz="0" iyy="0.00001" iyz="0" izz="0.000004"/>
    </inertial>
  </link>
  <joint name="rear_right_steering_joint" type="revolute">
    <origin xyz="0.676 0.361 0.0135"/>
    <parent link="base_link"/>
    <child link="rear_right_steering_link"/>
    <limit effort="5" lower="-2.1" upper="2.1" velocity="6.28"/>
    <axis xyz="0 0 1"/>
  </joint>
  <link name="rear_right_steering_link">
    <visual>
      <geometry>
        <mesh filename="package://h500_description/meshes/DAE/suspension/rear_right_link.dae"/>
      </geometry>
    </visual>
    <collision>
      <geometry>
        <mesh filename="package://h500_description/meshes/DAE/suspension/rear_right_link.dae"/>
      </geometry>
    </collision>
    <inertial>
      <origin xyz="0 0 -0.02"/>
      <mass value="0.15"/>
      <inertia ixx="0.00001" ixy="0" ixz="0" iyy="0.00001" iyz="0" izz="0.000004"/>
    </inertial>
  </link>
  <joint name="rear_left_steering_joint" type="revolute">
    <origin xyz="0.676 -0.3495 0.0135"/>
    <parent link="base_link"/>
    <child link="rear_left_steering_link"/>
    <limit effort="5" lower="-2.1" upper="2.1" velocity="6.28"/>
    <axis xyz="0 0 1"/>
  </joint>
  <link name="rear_left_steering_link">
    <visual>
      <geometry>
        <mesh filename="package://h500_description/meshes/DAE/suspension/rear_left_link.dae"/>
      </geometry>
    </visual>
    <collision>
      <geometry>
        <mesh filename="package://h500_description/meshes/DAE/suspension/rear_left_link.dae"/>
      </geometry>
    </collision>
    <inertial>
      <origin xyz="0 0 -0.02"/>
      <mass value="0.15"/>
      <inertia ixx="0.00001" ixy="0" ixz="0" iyy="0.00001" iyz="0" izz="0.000004"/>
    </inertial>
  </link>
  <joint name="ffr_wheel_joint" type="continuous">
    <origin rpy="0 0 3.14159274" xyz="-0.0004 0.07 0.118"/>
    <parent link="front_right_steering_link"/>
    <child link="ffr_wheel_link"/>
    <limit effort="1.5" velocity="20"/>
    <axis xyz="0 1 0"/>
  </joint>
  <link name="ffr_wheel_link">
    <visual>
      <geometry>
        <mesh filename="package://h500_description/meshes/DAE/wheel/H500_wheel.dae"/>
      </geometry>
    </visual>
    <collision>
      <geometry>
        <mesh filename="package://h500_description/meshes/DAE/wheel/H500_wheel.dae"/>
      </geometry>
    </collision>
    <inertial>
      <origin xyz="0.0 -0.007 -0.0"/>
      <mass value="0.05"/>
      <inertia ixx="0.00001" ixy="0" ixz="0" iyy="0.000018" iyz="0" izz="0.00001"/>
    </inertial>
  </link>
  <joint name="ffl_wheel_joint" type="continuous">
    <origin rpy="0 0 3.14159274" xyz="-0.0004 -0.32 0.118"/>
    <parent link="front_left_steering_link"/>
    <child link="ffl_wheel_link"/>
    <limit effort="1.5" velocity="20"/>
    <axis xyz="0 -1 0"/>
  </joint>
  <link name="ffl_wheel_link">
    <visual>
      <geometry>
        <mesh filename="package://h500_description/meshes/DAE/wheel/H500_wheel.dae"/>
      </geometry>
    </visual>
    <collision>
      <geometry>
        <mesh filename="package://h500_description/meshes/DAE/wheel/H500_wheel.dae"/>
      </geometry>
    </collision>
    <inertial>
      <origin xyz="0.0 -0.007 -0.0"/>
      <mass value="0.05"/>
      <inertia ixx="0.00001" ixy="0" ixz="0" iyy="0.000018" iyz="0" izz="0.00001"/>
    </inertial>
  </link>
  <joint name="rfr_wheel_joint" type="continuous">
    <origin rpy="0 0 3.14159274" xyz="-0.0004 0.07 0.118"/>
    <parent link="rear_right_steering_link"/>
    <child link="rfr_wheel_link"/>
    <limit effort="1.5" velocity="20"/>
    <axis xyz="0 1 0"/>
  </joint>
  <link name="rfr_wheel_link">
    <visual>
      <geometry>
        <mesh filename="package://h500_description/meshes/DAE/wheel/H500_wheel.dae"/>
      </geometry>
    </visual>
    <collision>
      <geometry>
        <mesh filename="package://h500_description/meshes/DAE/wheel/H500_wheel.dae"/>
      </geometry>
    </collision>
    <inertial>
      <origin xyz="0.0 -0.007 -0.0"/>
      <mass value="0.05"/>
      <inertia ixx="0.00001" ixy="0" ixz="0" iyy="0.000018" iyz="0" izz="0.00001"/>
    </inertial>
  </link>
  <joint name="rfl_wheel_joint" type="continuous">
    <origin rpy="0 0 3.14159274" xyz="-0.0004 -0.32 0.118"/>
    <parent link="rear_left_steering_link"/>
    <child link="rfl_wheel_link"/>
    <limit effort="1.5" velocity="20"/>
    <axis xyz="0 -1 0"/>
  </joint>
  <link name="rfl_wheel_link">
    <visual>
      <geometry>
        <mesh filename="package://h500_description/meshes/DAE/wheel/H500_wheel.dae"/>
      </geometry>
    </visual>
    <collision>
      <geometry>
        <mesh filename="package://h500_description/meshes/DAE/wheel/H500_wheel.dae"/>
      </geometry>
    </collision>
    <inertial>
      <origin xyz="0.0 -0.007 -0.0"/>
      <mass value="0.05"/>
      <inertia ixx="0.00001" ixy="0" ixz="0" iyy="0.000018" iyz="0" izz="0.00001"/>
    </inertial>
  </link>
  <transmission name="ffr_wheel_trans">
    <type>transmission_interface/SimpleTransmission</type>
    <joint name="ffr_wheel_joint">
      <hardwareInterface>hardware_interface/VelocityJointInterface</hardwareInterface>
    </joint>
    <actuator name="ffr_wheel_motor">
      <hardwareInterface>hardware_interface/VelocityJointInterface</hardwareInterface>
      <mechanicalReduction>1</mechanicalReduction>
    </actuator>
  </transmission>
  <transmission name="ffl_wheel_trans">
    <type>transmission_interface/SimpleTransmission</type>
    <joint name="ffl_wheel_joint">
      <hardwareInterface>hardware_interface/VelocityJointInterface</hardwareInterface>
    </joint>
    <actuator name="ffl_wheel_motor">
      <hardwareInterface>hardware_interface/VelocityJointInterface</hardwareInterface>
      <mechanicalReduction>1</mechanicalReduction>
    </actuator>
  </transmission>
  <transmission name="rfr_wheel_trans">
    <type>transmission_interface/SimpleTransmission</type>
    <joint name="rfr_wheel_joint">
      <hardwareInterface>hardware_interface/VelocityJointInterface</hardwareInterface>
    </joint>
    <actuator name="rfr_wheel_motor">
      <hardwareInterface>hardware_interface/VelocityJointInterface</hardwareInterface>
      <mechanicalReduction>1</mechanicalReduction>
    </actuator>
  </transmission>
  <transmission name="rfl_wheel_trans">
    <type>transmission_interface/SimpleTransmission</type>
    <joint name="rfl_wheel_joint">
      <hardwareInterface>hardware_interface/VelocityJointInterface</hardwareInterface>
    </joint>
    <actuator name="rfl_wheel_motor">
      <hardwareInterface>hardware_interface/VelocityJointInterface</hardwareInterface>
      <mechanicalReduction>1</mechanicalReduction>
    </actuator>
  </transmission>
  <transmission name="front_right_steering_trans">
    <type>transmission_interface/SimpleTransmission</type>
    <joint name="front_right_steering_joint">
      <hardwareInterface>hardware_interface/PositionJointInterface</hardwareInterface>
    </joint>
    <actuator name="front_right_steering_motor">
      <hardwareInterface>hardware_interface/PositionJointInterface</hardwareInterface>
      <mechanicalReduction>30</mechanicalReduction>
    </actuator>
  </transmission>
  <transmission name="front_left_steering_trans">
    <type>transmission_interface/SimpleTransmission</type>
    <joint name="front_left_steering_joint">
      <hardwareInterface>hardware_interface/PositionJointInterface</hardwareInterface>
    </joint>
    <actuator name="front_left_steering_motor">
      <hardwareInterface>hardware_interface/PositionJointInterface</hardwareInterface>
      <mechanicalReduction>30</mechanicalReduction>
    </actuator>
  </transmission>
  <transmission name="rear_right_steering_trans">
    <type>transmission_interface/SimpleTransmission</type>
    <joint name="rear_right_steering_joint">
      <hardwareInterface>hardware_interface/PositionJointInterface</hardwareInterface>
    </joint>
    <actuator name="rear_right_steering_motor">
      <hardwareInterface>hardware_interface/PositionJointInterface</hardwareInterface>
      <mechanicalReduction>30</mechanicalReduction>
    </actuator>
  </transmission>
  <transmission name="rear_left_steering_trans">
    <type>transmission_interface/SimpleTransmission</type>
    <joint name="rear_left_steering_joint">
      <hardwareInterface>hardware_interface/PositionJointInterface</hardwareInterface>
    </joint>
    <actuator name="rear_left_steering_motor">
      <hardwareInterface>hardware_interface/PositionJointInterface</hardwareInterface>
      <mechanicalReduction>30</mechanicalReduction>
    </actuator>
  </transmission>
  <!-- =============== Gazebo =============== -->
  <gazebo>
    <plugin filename="libgazebo_ros_control.so" name="gazebo_ros_control">
    </plugin>
  </gazebo>
  <gazebo reference="base_link">
    <selfCollide>false</selfCollide>
    <mu1 value="0.05"/>
    <mu2 value="0.05"/>
  </gazebo>
  <gazebo reference="fr_wheel_link">
    <selfCollide>false</selfCollide>
    <mu1 value="1.2"/>
    <mu2 value="1.2"/>
  </gazebo>
  <gazebo reference="fl_wheel_link">
    <selfCollide>false</selfCollide>
    <mu1 value="1.2"/>
    <mu2 value="1.2"/>
  </gazebo>
  <gazebo reference="rr_wheel_link">
    <selfCollide>false</selfCollide>
    <mu1 value="1.2"/>
    <mu2 value="1.2"/>
  </gazebo>
  <gazebo reference="rl_wheel_link">
    <selfCollide>false</selfCollide>
    <mu1 value="1.2"/>
    <mu2 value="1.2"/>
  </gazebo>
  <gazebo reference="front_right_steering_link">
    <selfCollide>false</selfCollide>
    <mu1 value="0.05"/>
    <mu2 value="0.05"/>
  </gazebo>
  <gazebo reference="front_left_steering_link">
    <selfCollide>false</selfCollide>
    <mu1 value="0.05"/>
    <mu2 value="0.05"/>
  </gazebo>
  <gazebo reference="rear_right_steering_link">
    <selfCollide>false</selfCollide>
    <mu1 value="0.05"/>
    <mu2 value="0.05"/>
  </gazebo>
  <gazebo reference="rear_left_steering_link">
    <selfCollide>false</selfCollide>
    <mu1 value="0.05"/>
    <mu2 value="0.05"/>
  </gazebo>
</robot>
