<?xml version="1.0" encoding="utf-8"?>
<!-- =================================================================================== -->
<!-- |    This document was autogenerated by xacro from /home/parlab/github/hada_explorer_ws/src/h500_description/h500_sprayer/h500.urdf.xacro | -->
<!-- |    EDITING THIS FILE BY HAND IS NOT RECOMMENDED                                 | -->
<!-- =================================================================================== -->
<robot name="h500_sprayer">
  <material name="blue">
    <color rgba="0 0 0.8 1"/>
  </material>
  <material name="yellow">
    <color rgba="0.8 0.8 0 1"/>
  </material>
  <!-- =============== Link & Joint =============== -->
  <!-- Base -->
<!--  <link name="base_footprint"/>
  <joint name="base_link_joint" type="fixed">
    <origin rpy="0 0 0" xyz="0 0 0.15"/>
    <parent link="base_footprint"/>
    <child link="base_link"/>
  </joint> -->
  <link name="base_link">
    <visual>
      <geometry>
        <mesh filename="package://h500_description/meshes/DAE/base/h500_body.dae"/>
      </geometry>
    </visual>
    <collision>
      <geometry>
        <mesh filename="package://h500_description/meshes/DAE/base/h500_body.dae"/>
      </geometry>
    </collision>
    <inertial>
      <origin xyz="0 0 0.017"/>
      <mass value="1.2"/>
      <inertia ixx="0.0001873" ixy="0" ixz="0" iyy="0.000055" iyz="0" izz="0.0002283"/>
    </inertial>
  </link>

<!--marker base link-->
  <joint name="marker_base_link_joint" type="fixed">
    <origin rpy="0 0 0" xyz="0 0 0.15"/>
    <parent link="base_link"/>
    <child link="marker_base_link"/>
  </joint>
  <link name="marker_base_link">
    <visual>
      <origin rpy="0 0 0" xyz="0 0 0"/>
      <geometry>
        <box size="1.118 0.699 0.1"/>
      </geometry>
      <material name="green"/>
    </visual>
    <collision>
      <origin rpy="0 0 0" xyz="0 0 0"/>
      <geometry>
        <box size="1.118 0.699 0.1"/> <!-- <box size="0.5 0.3 0.1"/> -->
      </geometry>
    </collision>
    <inertial>
      <origin rpy="0 0 0" xyz="0 0 0"/>
      <mass value="5"/>
      <inertia ixx="0.0416666666667" ixy="0.0" ixz="0.0" iyy="0.108333333333" iyz="0.0" izz="0.141666666667"/>
    </inertial>
  </link>
<!--end of marker base link-->    
    
<!--editing front right steer-->    
  <joint name="front_right_steer_joint" type="revolute">
    <origin xyz="-0.442 0.361 0.0135"/>
    <parent link="base_link"/>
    <child link="front_right_steering_link"/>
    <limit effort="5" lower="-2.1" upper="2.1" velocity="6.28"/>
    <axis xyz="0 0 2."/>
  </joint>
   
  <link name="front_right_steering_link">
    <visual>
      <geometry>
        <mesh filename="package://h500_description/meshes/DAE/suspension/front_right_link.dae"/>
      </geometry>
    </visual>
    <collision>
      <geometry>
        <mesh filename="package://h500_description/meshes/DAE/suspension/front_right_link.dae"/>
      </geometry>
    </collision>
    <inertial>
      <origin xyz="0 0 -0.02"/>
      <mass value="0.15"/>
      <inertia ixx="0.00001" ixy="0" ixz="0" iyy="0.00001" iyz="0" izz="0.000004"/>
    </inertial>
  </link>
<!--end of front right steering section -->
    
<!-- front right steering steering marker -->
  <link name="marker_front_right_steer_link">
    <visual>
      <origin rpy="0 0 0" xyz="0 0 0"/>
      <geometry>
        <cylinder length="0.02" radius="0.1"/>
      </geometry>
      <material name="blue"/>
    </visual>
    <collision>
      <origin rpy="0 0 0" xyz="0 0 0"/>
      <geometry>
        <cylinder length="0.02" radius="0.20"/>
      </geometry>
    </collision>
    <inertial>
      <origin rpy="0 0 0" xyz="0 0 0"/>
      <mass value="1"/>
      <inertia ixx="0.000658333333333" ixy="0.0" ixz="0.0" iyy="0.000658333333333" iyz="0.0" izz="0.00125"/>
    </inertial>
  </link>
  <joint name="marker_front_right_steer_joint" type="revolute">
    <parent link="front_right_steering_link"/>
    <child link="marker_front_right_steer_link"/>
    <origin rpy="0 0 0" xyz="0 0 0.43"/>
    <axis xyz="0 0 1"/>
    <limit effort="10.0" lower="-0.785398163397" upper="0.785398163397" velocity="5.0"/>
  </joint>
<!-- end of front right steering steering marker -->

<!--front steer middle-->    
  <link name="front_steer_link">
    <visual>
      <origin rpy="0 0 0" xyz="0 0 0"/>
      <geometry>
        <cylinder length="0.02" radius="0.10"/>
      </geometry>
      <material name="yellow"/>
    </visual>
    <collision>
      <origin rpy="0 0 0" xyz="0 0 0"/>
      <geometry>
        <cylinder length="0.02" radius="0.05"/>
      </geometry>
    </collision>
    <inertial>
      <origin rpy="0 0 0" xyz="0 0 0"/>
      <mass value="1"/>
      <inertia ixx="0.000658333333333" ixy="0.0" ixz="0.0" iyy="0.000658333333333" iyz="0.0" izz="0.00125"/>
    </inertial>
  </link>
  <joint name="front_steer_joint" type="revolute">
    <parent link="base_link"/>
    <child link="front_steer_link"/>
    <origin rpy="0 0 0" xyz="-0.442 0.0 0.45"/> <!-- xyz="0.2 0 0.12 -->
    <axis xyz="0 0 1"/>
    <limit effort="10.0" lower="-3.14159265359" upper="3.14159265359" velocity="5.0"/>
  </joint> 
<!--end of front steer middle-->  
    
<!--front left steering section -->
  <joint name="front_left_steer_joint" type="revolute">
    <origin xyz="-0.442 -0.3495 0.0135"/>
    <parent link="base_link"/>
    <child link="front_left_steering_link"/>
    <limit effort="5" lower="-2.1" upper="2.1" velocity="6.28"/>
    <axis xyz="0 0 1"/>
  </joint>
  <link name="front_left_steering_link">
    <visual>
      <geometry>
        <mesh filename="package://h500_description/meshes/DAE/suspension/front_left_link.dae"/>
      </geometry>
    </visual>
    <collision>
      <geometry>
        <mesh filename="package://h500_description/meshes/DAE/suspension/front_left_link.dae"/>
      </geometry>
    </collision>
    <inertial>
      <origin xyz="0 0 -0.02"/>
      <mass value="0.15"/>
      <inertia ixx="0.00001" ixy="0" ixz="0" iyy="0.00001" iyz="0" izz="0.000004"/>
    </inertial>
  </link>
<!--end of front left steering section -->
    
<!-- front left steering steering marker -->
  <link name="marker_front_left_steer_link">
    <visual>
      <origin rpy="0 0 0" xyz="0 0 0"/>
      <geometry>
        <cylinder length="0.02" radius="0.1"/>
      </geometry>
      <material name="blue"/>
    </visual>
    <collision>
      <origin rpy="0 0 0" xyz="0 0 0"/>
      <geometry>
        <cylinder length="0.02" radius="0.1"/>
      </geometry>
    </collision>
    <inertial>
      <origin rpy="0 0 0" xyz="0 0 0"/>
      <mass value="1"/>
      <inertia ixx="0.000658333333333" ixy="0.0" ixz="0.0" iyy="0.000658333333333" iyz="0.0" izz="0.00125"/>
    </inertial>
  </link>
  <joint name="marker_front_left_steer_joint" type="revolute">
    <parent link="front_left_steering_link"/>
    <child link="marker_front_left_steer_link"/>
    <origin rpy="0 0 0" xyz="0 0 0.43"/> <!-- <origin rpy="0 0 0" xyz="0 0 0.43"/>-->
    <axis xyz="0 0 1"/>
    <limit effort="10.0" lower="-0.785398163397" upper="0.785398163397" velocity="5.0"/>
  </joint>
<!-- end of front left steering steering marker -->     
    
<!--rear right steering section -->     
  <joint name="rear_right_steering_joint" type="revolute">
    <origin xyz="0.676 0.361 0.0135"/>
    <parent link="base_link"/>
    <child link="rear_right_steering_link"/>
    <limit effort="5" lower="-2.1" upper="2.1" velocity="6.28"/>
    <axis xyz="0 0 1"/>
  </joint>
   
  <link name="rear_right_steering_link">
    <visual>
      <geometry>
        <mesh filename="package://h500_description/meshes/DAE/suspension/rear_right_link.dae"/>
      </geometry>
    </visual>
    <collision>
      <geometry>
        <mesh filename="package://h500_description/meshes/DAE/suspension/rear_right_link.dae"/>
      </geometry>
    </collision>
    <inertial>
      <origin xyz="0 0 -0.02"/>
      <mass value="0.15"/>
      <inertia ixx="0.00001" ixy="0" ixz="0" iyy="0.00001" iyz="0" izz="0.000004"/>
    </inertial>
  </link>
<!--end of rear right steering section -->
    
<!--rear left steering section -->    
  <joint name="rear_left_steering_joint" type="revolute">
    <origin xyz="0.676 -0.3495 0.0135"/>
    <parent link="base_link"/>
    <child link="rear_left_steering_link"/>
    <limit effort="5" lower="-2.1" upper="2.1" velocity="6.28"/>
    <axis xyz="0 0 1"/>
  </joint>
  <link name="rear_left_steering_link">
    <visual>
      <geometry>
        <mesh filename="package://h500_description/meshes/DAE/suspension/rear_left_link.dae"/>
      </geometry>
    </visual>
    <collision>
      <geometry>
        <mesh filename="package://h500_description/meshes/DAE/suspension/rear_left_link.dae"/>
      </geometry>
    </collision>
    <inertial>
      <origin xyz="0 0 -0.02"/>
      <mass value="0.15"/>
      <inertia ixx="0.00001" ixy="0" ixz="0" iyy="0.00001" iyz="0" izz="0.000004"/>
    </inertial>
  </link>
<!--end of rear left steering section -->    
    
<!--ffr_wheel_joint-->    
  <joint name="front_right_wheel_joint" type="continuous">
    <origin rpy="0 0 3.14159274" xyz="-0.0004 0.07 0.118"/>
    <parent link="front_right_steering_link"/>
    <child link="ffr_wheel_link"/>
    <limit effort="1.5" velocity="20"/>
    <axis xyz="0 1 0"/>
  </joint>
  <link name="ffr_wheel_link">
    <visual>
      <geometry>
        <mesh filename="package://h500_description/meshes/DAE/wheel/H500_wheel.dae"/>
      </geometry>
    </visual>
    <collision>
      <geometry>
        <mesh filename="package://h500_description/meshes/DAE/wheel/H500_wheel.dae"/>
      </geometry>
    </collision>
    <inertial>
      <origin xyz="0.0 -0.007 -0.0"/>
      <mass value="0.05"/>
      <inertia ixx="0.00001" ixy="0" ixz="0" iyy="0.000018" iyz="0" izz="0.00001"/>
    </inertial>
  </link>
<!--end of ffr wheel section-->
    
<!--ffl_wheel_joint-->    
  <joint name="front_left_wheel_joint" type="continuous">
    <origin rpy="0 0 3.14159274" xyz="-0.0004 -0.32 0.118"/>
    <parent link="front_left_steering_link"/>
    <child link="ffl_wheel_link"/>
    <limit effort="1.5" velocity="20"/>
    <axis xyz="0 -1 0"/>
  </joint>
  <link name="ffl_wheel_link">
    <visual>
      <geometry>
        <mesh filename="package://h500_description/meshes/DAE/wheel/H500_wheel.dae"/>
      </geometry>
    </visual>
    <collision>
      <geometry>
        <mesh filename="package://h500_description/meshes/DAE/wheel/H500_wheel.dae"/>
      </geometry>
    </collision>
    <inertial>
      <origin xyz="0.0 -0.007 -0.0"/>
      <mass value="0.05"/>
      <inertia ixx="0.00001" ixy="0" ixz="0" iyy="0.000018" iyz="0" izz="0.00001"/>
    </inertial>
  </link>
<!--end of ffl wheel section-->
    
<!--rfr wheel section-->    
  <joint name="rear_right_wheel_joint" type="continuous">
    <origin rpy="0 0 3.14159274" xyz="-0.0004 0.07 0.118"/>
    <parent link="rear_right_steering_link"/>
    <child link="rfr_wheel_link"/>
    <limit effort="1.5" velocity="20"/>
    <axis xyz="0 1 0"/>
  </joint>
  <link name="rfr_wheel_link">
    <visual>
      <geometry>
        <mesh filename="package://h500_description/meshes/DAE/wheel/H500_wheel.dae"/>
      </geometry>
    </visual>
    <collision>
      <geometry>
        <mesh filename="package://h500_description/meshes/DAE/wheel/H500_wheel.dae"/>
      </geometry>
    </collision>
    <inertial>
      <origin xyz="0.0 -0.007 -0.0"/>
      <mass value="0.05"/>
      <inertia ixx="0.00001" ixy="0" ixz="0" iyy="0.000018" iyz="0" izz="0.00001"/>
    </inertial>
  </link>
<!--end of rfr wheel section-->    

<!--rfl wheel section-->    
  <joint name="rear_left_wheel_joint" type="continuous">
    <origin rpy="0 0 3.14159274" xyz="-0.0004 -0.32 0.118"/>
    <parent link="rear_left_steering_link"/>
    <child link="rfl_wheel_link"/>
    <limit effort="1.5" velocity="20"/>
    <axis xyz="0 -1 0"/>
  </joint>
  <link name="rfl_wheel_link">
    <visual>
      <geometry>
        <mesh filename="package://h500_description/meshes/DAE/wheel/H500_wheel.dae"/>
      </geometry>
    </visual>
    <collision>
      <geometry>
        <mesh filename="package://h500_description/meshes/DAE/wheel/H500_wheel.dae"/>
      </geometry>
    </collision>
    <inertial>
      <origin xyz="0.0 -0.007 -0.0"/>
      <mass value="0.05"/>
      <inertia ixx="0.00001" ixy="0" ixz="0" iyy="0.000018" iyz="0" izz="0.00001"/>
    </inertial>
  </link>
<!--end of rfl wheel section-->
    
<!--rear wheel link-->
  <link name="rear_wheel_link">
    <visual>
      <origin rpy="0 0 0" xyz="0 0 0"/>
      <geometry>
        <cylinder length="0.04" radius="0.1"/> <!-- <cylinder length="0.04" radius="0.025"/> -->
      </geometry>
      <material name="yellow"/>
    </visual>
    <collision>
      <origin rpy="0 0 0" xyz="0 0 0"/>
      <geometry>
        <cylinder length="0.04" radius="0.1"/> <cylinder length="0.04" radius="0.025"/>
      </geometry>
    </collision>
    <inertial>
      <origin rpy="0 0 0" xyz="0 0 0"/>
      <mass value="0.03125"/>
      <inertia ixx="9.04947916667e-06" ixy="0.0" ixz="0.0" iyy="9.04947916667e-06" iyz="0.0" izz="9.765625e-06"/>
    </inertial>
  </link>
  <joint name="rear_wheel_joint" type="continuous">
    <parent link="base_link"/>
    <child link="rear_wheel_link"/>
    <origin rpy="-1.57079632679 0 0" xyz="0.676 0 0.1315"/>
    <axis xyz="0 0 1"/>
  </joint>
  <transmission name="rear_wheel_joint_trans">
    <type>transmission_interface/SimpleTransmission</type>
    <actuator name="rear_wheel_joint_motor">
      <mechanicalReduction>1</mechanicalReduction>
      <hardwareInterface>hardware_interface/VelocityJointInterface</hardwareInterface>
    </actuator>
    <joint name="rear_wheel_joint">
      <hardwareInterface>hardware_interface/VelocityJointInterface</hardwareInterface>
    </joint>
  </transmission>
  <gazebo reference="rear_wheel_link">
    <material>Gazebo/Yellow</material>
  </gazebo>
<!--end of rear wheel link-->    
    
  <transmission name="front_right_wheel_trans">
    <type>transmission_interface/SimpleTransmission</type>
    <joint name="ront_right_wheel_joint">
      <hardwareInterface>hardware_interface/VelocityJointInterface</hardwareInterface>
    </joint>
    <actuator name="front_right_wheel_motor">
      <hardwareInterface>hardware_interface/VelocityJointInterface</hardwareInterface>
      <mechanicalReduction>1</mechanicalReduction>
    </actuator>
  </transmission>
  <transmission name="front_left_wheel_trans">
    <type>transmission_interface/SimpleTransmission</type>
    <joint name="front_left_wheel_joint">
      <hardwareInterface>hardware_interface/VelocityJointInterface</hardwareInterface>
    </joint>
    <actuator name="ffl_wheel_motor">
      <hardwareInterface>hardware_interface/VelocityJointInterface</hardwareInterface>
      <mechanicalReduction>1</mechanicalReduction>
    </actuator>
  </transmission>
  <transmission name="rfr_wheel_trans">
    <type>transmission_interface/SimpleTransmission</type>
    <joint name="rfr_wheel_joint">
      <hardwareInterface>hardware_interface/VelocityJointInterface</hardwareInterface>
    </joint>
    <actuator name="rfr_wheel_motor">
      <hardwareInterface>hardware_interface/VelocityJointInterface</hardwareInterface>
      <mechanicalReduction>1</mechanicalReduction>
    </actuator>
  </transmission>
  <transmission name="rfl_wheel_trans">
    <type>transmission_interface/SimpleTransmission</type>
    <joint name="rfl_wheel_joint">
      <hardwareInterface>hardware_interface/VelocityJointInterface</hardwareInterface>
    </joint>
    <actuator name="rfl_wheel_motor">
      <hardwareInterface>hardware_interface/VelocityJointInterface</hardwareInterface>
      <mechanicalReduction>1</mechanicalReduction>
    </actuator>
  </transmission>
  <transmission name="front_right_steer_trans">
    <type>transmission_interface/SimpleTransmission</type>
    <joint name="front_right_steer_joint">
      <hardwareInterface>hardware_interface/PositionJointInterface</hardwareInterface>
    </joint>
    <actuator name="front_right_steer_motor">
      <hardwareInterface>hardware_interface/PositionJointInterface</hardwareInterface>
      <mechanicalReduction>30</mechanicalReduction>
    </actuator>
  </transmission>
  <transmission name="front_left_steer_trans">
    <type>transmission_interface/SimpleTransmission</type>
    <joint name="front_left_steer_joint">
      <hardwareInterface>hardware_interface/PositionJointInterface</hardwareInterface>
    </joint>
    <actuator name="front_left_steer_motor">
      <hardwareInterface>hardware_interface/PositionJointInterface</hardwareInterface>
      <mechanicalReduction>30</mechanicalReduction>
    </actuator>
  </transmission>
  <transmission name="rear_right_steering_trans">
    <type>transmission_interface/SimpleTransmission</type>
    <joint name="rear_right_steering_joint">
      <hardwareInterface>hardware_interface/PositionJointInterface</hardwareInterface>
    </joint>
    <actuator name="rear_right_steering_motor">
      <hardwareInterface>hardware_interface/PositionJointInterface</hardwareInterface>
      <mechanicalReduction>30</mechanicalReduction>
    </actuator>
  </transmission>
  <transmission name="rear_left_steering_trans">
    <type>transmission_interface/SimpleTransmission</type>
    <joint name="rear_left_steering_joint">
      <hardwareInterface>hardware_interface/PositionJointInterface</hardwareInterface>
    </joint>
    <actuator name="rear_left_steering_motor">
      <hardwareInterface>hardware_interface/PositionJointInterface</hardwareInterface>
      <mechanicalReduction>30</mechanicalReduction>
    </actuator>
  </transmission>
  <!-- =============== Gazebo =============== -->
  <gazebo>
    <plugin filename="libgazebo_ros_control.so" name="gazebo_ros_control">
    </plugin>
  </gazebo>
  <gazebo reference="base_link">
    <selfCollide>false</selfCollide>
    <mu1 value="0.05"/>
    <mu2 value="0.05"/>
  </gazebo>
  <gazebo reference="fr_wheel_link">
    <selfCollide>false</selfCollide>
    <mu1 value="1.2"/>
    <mu2 value="1.2"/>
  </gazebo>
  <gazebo reference="fl_wheel_link">
    <selfCollide>false</selfCollide>
    <mu1 value="1.2"/>
    <mu2 value="1.2"/>
  </gazebo>
  <gazebo reference="rr_wheel_link">
    <selfCollide>false</selfCollide>
    <mu1 value="1.2"/>
    <mu2 value="1.2"/>
  </gazebo>
  <gazebo reference="rl_wheel_link">
    <selfCollide>false</selfCollide>
    <mu1 value="1.2"/>
    <mu2 value="1.2"/>
  </gazebo>
  <gazebo reference="front_right_steering_link">
    <selfCollide>false</selfCollide>
    <mu1 value="0.05"/>
    <mu2 value="0.05"/>
  </gazebo>
  <gazebo reference="front_left_steering_link">
    <selfCollide>false</selfCollide>
    <mu1 value="0.05"/>
    <mu2 value="0.05"/>
  </gazebo>
  <gazebo reference="rear_right_steering_link">
    <selfCollide>false</selfCollide>
    <mu1 value="0.05"/>
    <mu2 value="0.05"/>
  </gazebo>
  <gazebo reference="rear_left_steering_link">
    <selfCollide>false</selfCollide>
    <mu1 value="0.05"/>
    <mu2 value="0.05"/>
  </gazebo>
</robot>
